Workbook

Sheet RESUMO
B2: MOVIMENTAÇÃO PATRIMONIAL HTSP - DEZEMBRO 2020
B4: PLANO CONTA | C4: DESCRIÇÃO | D4: SALDO 31/12/2019 | E4: AQUISIÇÕES 2020 | F4: Participações CSC Alfa 2020 | G4: TRANSF. PROJETOS 2020 | H4: DEPRECIAÇÃO 2020 | I4: BAIXAS 2020 | J4: SALDO 31/12/2020 | K4: check saldo
B5: 112000 | C5: IMOBILIZADO | D5: 39583781 | E5: =E6 -> 2485492.8 | F5: =F6 -> -829781.7 | G5: =G6 -> -206.45 | H5: =H6 -> -9500236.5 | I5: =I6 -> -13939.78 | J5: =J6+J109 -> 31725110 | K5: =VLOOKUP(B5,'Balancete Contab. 12 2020'!A:G,7,0)-J5 -> -0.00019998476
B6: 115800 | C6: IMOBILIZADO | D6: 38221525 | E6: =RESUMO!E35+RESUMO!E72 -> 2485492.8 | F6: =F35+F38+F72 -> -829781.7 | G6: =G128*-1 -> -206.45 | H6: =depreciações!O5 -> -9500236.5 | I6: =SUM(I35+I38-I72)*-1 -> -13939.78 | J6: =D6+E6+F6+G6+H6+I6 -> 30362853 | K6: =VLOOKUP(B6,'Balancete Contab. 12 2020'!A:G,7,0)-J6 -> -0.00019998848
B7: 116085 | C7: EDIFICAÇÕES | D7: 41779372 | E7: =adições!O7 -> 0 | I7: =baixas!O8 -> 0 | J7: =D7+E7-I7 -> 41779372 | K7: =VLOOKUP(B7,'Balancete Contab. 12 2020'!A:G,7,0)-J7 -> 0
B8: 116090 | C8: INSTALAÇÕES | D8: 40892649 | E8: =adições!O8 -> 3600 | F8: ='participações CSC Alfa'!O9 -> -393083.34 | G8: ='tranf. proj'!O7 -> 699612.77 | J8: =D8+E8-I8+G8+F8 -> 41202778 | K8: =VLOOKUP(B8,'Balancete Contab. 12 2020'!A:G,7,0)-J8 -> 0
B9: 116095 | C9: INSTALAÇÕES - CSC HTSP | D9: 253171.52 | E9: =adições!O9 -> 7150 | F9: ='participações CSC Alfa'!O10 -> 393083.34 | G9: ='tranf. proj'!O8 -> 0 | J9: =D9+E9-I9+G9+F9 -> 653404.86 | K9: =VLOOKUP(B9,'Balancete Contab. 12 2020'!A:G,7,0)-J9 -> 0
B10: 116097 | C10: INSTALAÇÕES - CSC PARTICIPANTES | D10: -419319.34 | E10: =adições!O10 -> 0 | F10: ='participações CSC Alfa'!O11 -> -381618.9 | J10: =D10+E10-I10+G10+F10 -> -800938.24 | K10: =VLOOKUP(B10,'Balancete Contab. 12 2020'!A:G,7,0)-J10 -> 0
B11: 118110 | C11: MÁQUINAS E EQUIPAMENTOS | D11: 3849680.5 | E11: =adições!O11 -> 142854.44 | F11: ='participações CSC Alfa'!O13 -> -68454.79 | G11: ='tranf. proj'!O11 -> 90747.09 | I11: =baixas!O13 -> 8391.42 | J11: =D11+E11-I11+G11+F11 -> 4006435.8 | K11: =VLOOKUP(B11,'Balancete Contab. 12 2020'!A:G,7,0)-J11 -> 0
B12: 118115 | C12: MÁQUINAS E EQUIPAMENTOS - CSC HTSP | D12: 41832.64 | F12: ='participações CSC Alfa'!O14 -> 68454.79 | G12: ='tranf. proj'!O12 -> 0 | J12: =D12+E12-I12+G12+F12 -> 110287.43 | K12: =VLOOKUP(B12,'Balancete Contab. 12 2020'!A:G,7,0)-J12 -> 0
B13: 118120 | C13: MÁQUINAS E EQUIPAMENTOS - CSC PARTICIPANTES | D13: -38907.03 | F13: ='participações CSC Alfa'!O15 -> -74741.27 | J13: =D13+E13-I13+G13+F13 -> -113648.3 | K13: =VLOOKUP(B13,'Balancete Contab. 12 2020'!A:G,7,0)-J13 -> 0
B14: 118135 | C14: EQUIPAMENTO PROC. DADOS | D14: 1842573.9 | E14: =adições!O13 -> 43615.3 | F14: ='participações CSC Alfa'!O16 -> -139595 | G14: ='tranf. proj'!O13 -> 120016.15 | I14: =baixas!O15 -> 62454.96 | J14: =D14+E14-I14+G14+F14 -> 1804155.3 | K14: =VLOOKUP(B14,'Balancete Contab. 12 2020'!A:G,7,0)-J14 -> 0
B15: 118140 | C15: EQUIPAMENTO PROC. DADOS - ARREDAMENTO MERCANTIL | D15: 249438.86 | E15: =adições!O14 -> 0 | J15: =D15+E15-I15+G15+F15 -> 249438.86 | K15: =VLOOKUP(B15,'Balancete Contab. 12 2020'!A:G,7,0)-J15 -> 0
B16: 118150 | C16: EQUIPAMENTO PROC. DADOS - CSC HTSP | D16: 205720.51 | E16: =adições!O15 -> 0 | F16: ='participações CSC Alfa'!O18 -> 139595 | G16: ='tranf. proj'!O15 -> 0 | J16: =D16+E16-I16+G16+F16 -> 345315.51 | K16: =VLOOKUP(B16,'Balancete Contab. 12 2020'!A:G,7,0)-J16 -> 0
B17: 118155 | C17: EQUIPAMENTO PROC. DADOS - CSC PARTICIPANTES | D17: -284257.67 | E17: =adições!O16 -> 0 | F17: ='participações CSC Alfa'!O19 -> -120868.19 | J17: =D17+E17-I17+G17+F17 -> -405125.86 | K17: =VLOOKUP(B17,'Balancete Contab. 12 2020'!A:G,7,0)-J17 -> 0
B18: 119155 | C18: MÓVEIS E UTENSÍLIOS | D18: 12028900 | E18: =adições!O17 -> 241193.61 | F18: ='participações CSC Alfa'!O20 -> -208636.94 | G18: ='tranf. proj'!O17 -> 217647.96 | I18: =baixas!O19 -> 18119.2 | J18: =D18+E18-I18+G18+F18 -> 12260986 | K18: =VLOOKUP(B18,'Balancete Contab. 12 2020'!A:G,7,0)-J18 -> 0
B19: 119160 | C19: MÓVEIS E UTENSÍLIOS - CSC HTSP | D19: 163107.73 | E19: =adições!O18 -> 0 | F19: ='participações CSC Alfa'!O21 -> 208636.94 | G19: ='tranf. proj'!D18 -> 0 | J19: =D19+E19-I19+G19+F19 -> 371744.67 | K19: =VLOOKUP(B19,'Balancete Contab. 12 2020'!A:G,7,0)-J19 -> 0
B20: 119162 | C20: MÓVEIS E UTENSÍLIOS - CSC PARTICIPANTES | D20: -297875.59 | E20: =adições!O19 -> 0 | F20: ='participações CSC Alfa'!O22 -> -140697.96 | J20: =D20+E20-I20+G20+F20 -> -438573.55 | K20: =VLOOKUP(B20,'Balancete Contab. 12 2020'!A:G,7,0)-J20 -> 0
B21: 120185 | C21: VEÍCULOS | D21: 288633.85 | E21: =adições!O20 -> 0 | I21: =baixas!O22 -> 0 | J21: =D21+E21-I21+G21+F21 -> 288633.85 | K21: =VLOOKUP(B21,'Balancete Contab. 12 2020'!A:G,7,0)-J21 -> 0
B22: 122200 | C22: OBRAS DE ARTE | D22: 299322.21 | E22: =adições!O21 -> 0 | I22: =baixas!O23 -> 0 | J22: =D22+E22-I22+G22+F22 -> 299322.21 | K22: =VLOOKUP(B22,'Balancete Contab. 12 2020'!A:G,7,0)-J22 -> 0
B23: 123505 | C23: MATERIAL DE SERVIÇO | D23: 588545.45 | E23: =adições!O22 -> 0 | F23: ='participações CSC Alfa'!O17 -> 0 | G23: ='tranf. proj'!O22 -> 6088.28 | I23: =VLOOKUP(B23,baixas!A:O,15,0) -> 0 | J23: =D23+E23-I23+G23+F23 -> 594633.73 | K23: =VLOOKUP(B23,'Balancete Contab. 12 2020'!A:G,7,0)-J23 -> 0
B24: 123510 | C24: VIDROS E CRISTAIS | D24: 62483.35 | E24: =adições!O23 -> 0 | G24: ='tranf. proj'!O23 -> 0 | I24: =baixas!O25 -> 0 | J24: =D24+E24-I24+G24+F24 -> 62483.35 | K24: =VLOOKUP(B24,'Balancete Contab. 12 2020'!A:G,7,0)-J24 -> 0
B25: 123515 | C25: LOUÇAS E PORCELANAS | D25: 309954.26 | E25: =adições!O24 -> 0 | G25: ='tranf. proj'!O24 -> 9510.24 | I25: =VLOOKUP(B25,baixas!A:O,15,0) -> 0 | J25: =D25+E25-I25+G25+F25 -> 319464.5 | K25: =VLOOKUP(B25,'Balancete Contab. 12 2020'!A:G,7,0)-J25 -> 0
B26: 123520 | C26: PRATARIA E INOX | D26: 191160.38 | E26: =adições!O25 -> 0 | G26: ='tranf. proj'!O25 -> 5364.88 | I26: =VLOOKUP(B26,baixas!A:O,15,0) -> 0 | J26: =D26+E26-I26+G26+F26 -> 196525.26 | K26: =VLOOKUP(B26,'Balancete Contab. 12 2020'!A:G,7,0)-J26 -> 0
B27: 123525 | C27: CONFECCÇÕES PARA CAMA | D27: 25987.87 | E27: =adições!O26 -> 0 | F27: ='participações CSC Alfa'!O23 -> 0 | I27: =VLOOKUP(B27,baixas!A:O,15,0) -> 0 | J27: =D27+E27-I27+G27+F27 -> 25987.87 | K27: 0
B28: 123530 | C28: MATERIAL SERVICO CSC PARTICIPANTES. | D28: -112.88 | F28: =VLOOKUP(B28,'participações CSC Alfa'!A:O,15,0) -> -2487.22 | I28: 0 | J28: =SUM(D28:I28) -> -2600.1 | K28: =VLOOKUP(B28,'Balancete Contab. 12 2020'!A:G,7,0)-J28 -> 0
B29: 123535 | C29: VIDROS E CRISTAIS CSC PARTICIPANTES. | D29: -85.2 | F29: =VLOOKUP(B29,'participações CSC Alfa'!A:O,15,0) -> -0.25 | I29: 0 | J29: =SUM(D29:I29) -> -85.45 | K29: =VLOOKUP(B29,'Balancete Contab. 12 2020'!A:G,7,0)-J29 -> 0
B30: 123540 | C30: LOUCAS E PORCELANA CSC PARTICIPANTE. | D30: -379.78 | F30: =VLOOKUP(B30,'participações CSC Alfa'!A:O,15,0) -> -8465.17 | I30: 0 | J30: =SUM(D30:I30) -> -8844.95 | K30: =VLOOKUP(B30,'Balancete Contab. 12 2020'!A:G,7,0)-J30 -> 0
B31: 123545 | C31: PRATARIA E INOX - CSC PARTICIPANTES. | D31: -99.34 | F31: =VLOOKUP(B31,'participações CSC Alfa'!A:O,15,0) -> -4775.02 | I31: 0 | J31: =SUM(D31:I31) -> -4874.36 | K31: =VLOOKUP(B31,'Balancete Contab. 12 2020'!A:G,7,0)-J31 -> 0
B32: 123800 | C32: DIREITO DE USO | D32: 28198190 | E32: =adições!O31 -> 0 | J32: =SUM(D32:I32) -> 28198190
B33: 124110 | C33: BENF IMOVEIS 3. QUIOSQUE LA BASQUE. | D33: 94959.72 | E33: =VLOOKUP(B33,adições!A:O,15,0) -> 0 | F33: 0 | G33: 0 | H33: 0 | I33: 0 | J33: =SUM(D33:I33) -> 94959.72 | K33: =VLOOKUP(B33,'Balancete Contab. 12 2020'!A:G,7,0)-J33 -> 0
D35: =SUM(D7:D33) -> 1.3032465e+08 | E35: =SUM(E7:E33) -> 438413.35 | F35: =SUM(F7:F33) -> -733653.98 | G35: =SUM(G7:G33) -> 1148987.4 | I35: =SUM(I11:I34) -> 88965.58 | J35: =SUM(J7:J33) -> 1.3108943e+08
D37: =D35-D38-D95 -> 43618790 | J37: =J35-J38-J95 -> 40765874
B38: 124210 | C38: (-) DEPRECIACOES ACUMULADAS.......... | D38: 86971219 | F38: =SUM(F39:F65) -> -1891.12 | H38: =SUM(H39:H66) -> 3739779.6 | I38: =SUM(I39:I66)*-1 -> -82507.8 | J38: =D38+H38+I38-F38 -> 90630382 | K38: =VLOOKUP(B38,'Balancete Contab. 12 2020'!A:G,7,0)+J38 -> -0.0029999912
B39: 124225 | C39: (-) EDIFICACOES. | D39: 40276176 | H39: =depreciações!O8 -> 320276.36 | I39: =baixas!O32 -> 0 | J39: =D39+H39-I39 -> 40596453 | K39: =VLOOKUP(B39,'Balancete Contab. 12 2020'!A:G,7,0)+J39 -> 0
B40: 124230 | C40: (-) INSTALACOES. | D40: 32662375 | F40: ='participações CSC Alfa'!O37 -> 0 | H40: =depreciações!O9 -> 2090051.7 | I40: =baixas!O33 -> 0 | J40: =D40+H40-I40+F40 -> 34752427 | K40: =VLOOKUP(B40,'Balancete Contab. 12 2020'!A:G,7,0)+J40 -> 0
B41: 124231 | C41: (-) INSTALACOES - CSC HTSP. | D41: 29712.02 | H41: =depreciações!O10 -> 62051.95 | J41: =D41+H41-I41+F41 -> 91763.97 | K41: =VLOOKUP(B41,'Balancete Contab. 12 2020'!A:G,7,0)+J41 -> 0
B42: 124232 | C42: (-) INSTALACOES - CSC PARTIC.. | D42: -25202.37 | F42: ='participações CSC Alfa'!O39 -> -556.92 | H42: =depreciações!O11 -> -54398.47 | J42: =D42+H42-I42-F42 -> -79043.92 | K42: =VLOOKUP(B42,'Balancete Contab. 12 2020'!A:G,7,0)+J42 -> 0
B43: 124235 | C43: (-) MAQUINAS E EQUIPAMENTOS. | D43: 2765330 | F43: 0 | H43: =depreciações!O12 -> 206394.41 | I43: =baixas!O35 -> 7910.08 | J43: =D43+H43-I43+F43 -> 2963814.3 | K43: =VLOOKUP(B43,'Balancete Contab. 12 2020'!A:G,7,0)+J43 -> -0.0029999996
B44: 124236 | C44: (-) MAQUINAS E EQUIPAMENTOS - CSC HTSP. | D44: 3926.78 | H44: =depreciações!O13 -> 9949.26 | J44: =D44+H44-I44+F44 -> 13876.04 | K44: =VLOOKUP(B44,'Balancete Contab. 12 2020'!A:G,7,0)+J44 -> 0
...

Sheet adições
A2: MOVIMENTAÇÃO PATRIMONIAL HTSP - DEZEMBRO 2020
A4: PLANO CONTA | B4: DESCRIÇÃO | C4: 43831 | D4: 43862 | E4: 43891 | F4: 43922 | G4: 43952 | H4: 43983 | I4: 44013 | J4: 44044 | K4: 44075 | L4: 44105 | M4: 44136 | N4: 44166 | O4: TOTAL 2020
O5: =O6+O36+O67 -> 2493321.8
C6: =SUM(C7:C33) -> 21188.26 | D6: 84571.92 | E6: 61611.72 | H6: =SUM(H7:H33) -> 665 | I6: 2910 | J6: =SUM(J7:J33) -> 57028.08 | K6: =SUM(K7:K33) -> 47597.5 | L6: =SUM(L7:L33) -> 36775.27 | M6: =SUM(M7:M33) -> 114509.6 | N6: =SUM(N7:N33) -> 11556 | O6: =SUM(C6:N6) -> 438413.35
A7: 116085 | B7: EDIFICAÇÕES | C7: 0 | D7: 0 | O7: =SUM(C7:N7) -> 0
A8: 116090 | B8: INSTALAÇÕES | C8: 0 | D8: 0 | E8: 3600 | O8: =SUM(C8:N8) -> 3600
A9: 116095 | B9: INSTALAÇÕES - CSC HTSP | C9: 0 | D9: 0 | L9: 7150 | O9: =SUM(C9:N9) -> 7150
A10: 116097 | B10: INSTALAÇÕES - CSC PARTICIPANTES | C10: 0 | D10: 0 | O10: =SUM(C10:N10) -> 0
A11: 118110 | B11: MÁQUINAS E EQUIPAMENTOS | C11: 0 | D11: 760.01 | E11: 44338.75 | I11: 1200 | J11: 47258.18 | K11: 47597.5 | L11: 1700 | O11: =SUM(C11:N11) -> 142854.44
A12: 118115 | B12: MÁQUINAS E EQUIPAMENTOS - CSC HTSP | C12: 0 | D12: 0 | O12: =SUM(C12:N12) -> 0
A13: 118135 | B13: EQUIPAMENTO PROC. DADOS | C13: 15360 | D13: 708.3 | E13: 6581 | M13: 9410 | N13: =VLOOKUP(A13,'Afixo Aquisição 12 20 '!A:F,6,0) -> 11556 | O13: =SUM(C13:N13) -> 43615.3
A14: 118140 | B14: EQUIPAMENTO PROC. DADOS - ARREDAMENTO MERCANTIL | C14: 0 | D14: 0 | O14: =SUM(C14:N14) -> 0
A15: 118150 | B15: EQUIPAMENTO PROC. DADOS - CSC HTSP | C15: 0 | D15: 0 | O15: =SUM(C15:N15) -> 0
A16: 118155 | B16: EQUIPAMENTO PROC. DADOS - CSC PARTICIPANTES | C16: 0 | D16: 0 | O16: =SUM(C16:N16) -> 0
A17: 119155 | B17: MÓVEIS E UTENSÍLIOS | C17: 5828.26 | D17: 83103.61 | E17: 7091.97 | H17: 665 | I17: 1710 | J17: 9769.9 | L17: 27925.27 | M17: 105099.6 | O17: =SUM(C17:N17) -> 241193.61
A18: 119160 | B18: MÓVEIS E UTENSÍLIOS - CSC HTSP | C18: 0 | D18: 0 | O18: =SUM(C18:N18) -> 0
A19: 119162 | B19: MÓVEIS E UTENSÍLIOS - CSC PARTICIPANTES | C19: 0 | D19: 0 | O19: =SUM(C19:N19) -> 0
A20: 120185 | B20: VEÍCULOS | C20: 0 | D20: 0 | O20: =SUM(C20:N20) -> 0
A21: 122200 | B21: OBRAS DE ARTE | C21: 0 | D21: 0 | O21: =SUM(C21:N21) -> 0
A22: 123505 | B22: MATERIAL DE SERVIÇO | C22: 0 | D22: 0 | O22: =SUM(C22:N22) -> 0
A23: 123510 | B23: VIDROS E CRISTAIS | C23: 0 | D23: 0 | O23: =SUM(C23:N23) -> 0
A24: 123515 | B24: LOUÇAS E PORCELANAS | C24: 0 | D24: 0 | O24: =SUM(C24:N24) -> 0
A25: 123520 | B25: PRATARIA E INOX | C25: 0 | D25: 0 | O25: =SUM(C25:N25) -> 0
A26: 123525 | B26: CONFECCÇÕES PARA CAMA | C26: 0 | D26: 0 | O26: =SUM(C26:N26) -> 0
A27: 123530 | B27: MATERIAL SERVICO CSC PARTICIPANTES. | C27: 0 | D27: 0 | O27: =SUM(C27:N27) -> 0
A28: 123535 | B28: VIDROS E CRISTAIS CSC PARTICIPANTES. | C28: 0 | D28: 0 | O28: =SUM(C28:N28) -> 0
A29: 123540 | B29: LOUCAS E PORCELANA CSC PARTICIPANTE. | C29: 0 | D29: 0 | O29: =SUM(C29:N29) -> 0
... A33: 124110 | B33: BENF IMOVEIS 3. QUIOSQUE LA BASQUE. | C33: 0 | D33: 0 | O33: =SUM(C33:N33) -> 0
A36: 125450 | B36: PROJETOS | C36: =SUM(C37:C49) -> 120435.17 | D36: =SUM(D37:D49) -> 0 | E36: 0 | F36: 1231472.1 | G36: =SUM(G37:G51) -> -256350.08 | H36: =SUM(H37:H51) -> 230957.76 | I36: 227570.09 | J36: 421059.15 | K36: 53131.89 | L36: =SUM(L38:L56) -> 73018.62 | M36: =SUM(M38:M56) -> 13227.93 | N36: =SUM(N38:N56) -> -67443.14 | O36: =SUM(C36:N36) -> 2047079.5
A37: 125501 | B37: PROJETO REFORMA SALAS DE EVENTOS | C37: 0 | D37: 0 | F37: 0 | O37: =SUM(C37:N37) -> 0
A38: 125502 | B38: PROJETO REFORMA GERAL APTOS NORTE/SUL | C38: 0 | D38: 0 | F38: 0 | O38: =SUM(C38:N38) -> 0
A39: 125503 | B39: PROJETO SISTEMA CFTV | C39: 0 | D39: 0 | F39: 0 | O39: =SUM(C39:N39) -> 0
A40: 125504 | B40: PROJETO REFORMA DE SALAS DA DIRETORIA | C40: 0 | D40: 0 | F40: 0 | O40: =SUM(C40:N40) -> 0
A41: 125505 | B41: PROJETO RETROFIT ILUMINAÇÃO HTSP | C41: 0 | D41: 0 | F41: 0 | O41: =SUM(C41:N41) -> 0
A42: 125507 | B42: PROJETO REFORMA CSC - FASE 2 | C42: 0 | D42: 0 | F42: 0 | O42: =SUM(C42:N42) -> 0
A43: 125508 | B43: PROJETO QUIOSQUE LA BASQUE TEC | C43: 0 | D43: 0 | F43: 0 | O43: =SUM(C43:N43) -> 0
A44: 125509 | B44: PROJETO REFORMA CSC - FASE 3 | C44: 0 | D44: 0 | F44: 0 | O44: =SUM(C44:N44) -> 0
A45: 125510 | B45: PROJETO REFORMA CSC - FASE 4 | C45: 0 | D45: 0 | F45: 0 | O45: =SUM(C45:N45) -> 0
A46: 125511 | B46: PROJETO REFORMA AMPLIACAO FASE 1. | C46: 0 | D46: 0 | F46: 0 | O46: =SUM(C46:N46) -> 0
A47: 125512 | B47: PROJETO AMPLIACAO REFEITORIO. | C47: 120435.17 | D47: 0 | F47: 0 | O47: =SUM(C47:N47) -> 120435.17
...

Sheet participações CSC Alfa
A2: MOVIMENTAÇÃO PATRIMONIAL HTSP - DEZEMBRO 2020
A4: PLANO CONTA | B4: DESCRIÇÃO | C4: 43831 | D4: 43862 | E4: 43891 | F4: 43922 | G4: 43952 | H4: 43983 | I4: 44013 | J4: 44044 | K4: 44075 | L4: 44105 | M4: 44136 | N4: 44166 | O4: TOTAL 2020
O6: =SUM(O7:O22) -> -711376.48
A7: 115075 | B7: IMOBILIZADO | G7: =SUM(G8:G33) -> 6549.84 | O7: =SUM(C7:N7) -> 6549.84
A8: 116085 | B8: EDIFICAÇÕES | O8: =SUM(C8:N8) -> 0
A9: 116090 | B9: INSTALAÇÕES | G9: -393083.34 | O9: =SUM(C9:N9) -> -393083.34
A10: 116095 | B10: INSTALAÇÕES - CSC HTSP | G10: 393083.34 | O10: =SUM(C10:N10) -> 393083.34
A11: 116097 | B11: INSTALAÇÕES - CSC PARTICIPANTES | C11: -7889.44 | F11: 145122.12 | G11: 3552.29 | L11: 2502.5 | M11: 234672.31 | N11: 3659.12 | O11: =SUM(C11:N11)*-1 -> -381618.9
A12: 117095 | B12: SIST. COMUNICAÇÕES | O12: =SUM(C12:N12) -> 0
A13: 118110 | B13: MÁQUINAS E EQUIPAMENTOS | G13: -68454.79 | O13: =SUM(C13:N13) -> -68454.79
A14: 118115 | B14: MÁQUINAS E EQUIPAMENTOS - CSC HTSP | G14: 68454.79 | O14: =SUM(C14:N14) -> 68454.79
A15: 118120 | B15: MÁQUINAS E EQUIPAMENTOS - CSC PARTICIPANTES | C15: -816.82 | F15: 57641.55 | G15: 60.51 | M15: 17856.05 | N15: -0.02 | O15: =SUM(C15:N15)*-1 -> -74741.27
A16: 118135 | B16: EQUIPAMENTO PROC. DADOS | F16: 0 | G16: -139595 | O16: =SUM(C16:N16) -> -139595
A17: 118140 | B17: EQUIPAMENTO PROC. DADOS - ARREDAMENTO MERCANTIL | F17: 0 | O17: =SUM(C17:N17) -> 0
A18: 118150 | B18: EQUIPAMENTO PROC. DADOS - CSC HTSP | F18: 0 | G18: 139595 | O18: =SUM(C18:N18) -> 139595
A19: 118155 | B19: EQUIPAMENTO PROC. DADOS - CSC PARTICIPANTES | C19: 3360.45 | F19: 0 | M19: 102341.15 | N19: 15166.59 | O19: =-SUM(C19:N19) -> -120868.19
A20: 119155 | B20: MÓVEIS E UTENSÍLIOS | F20: 0 | G20: -208636.94 | O20: =SUM(C20:N20) -> -208636.94
A21: 119160 | B21: MÓVEIS E UTENSÍLIOS - CSC HTSP | F21: 0 | G21: 208636.94 | O21: =SUM(C21:N21) -> 208636.94
A22: 119162 | B22: MÓVEIS E UTENSÍLIOS - CSC PARTICIPANTES | C22: -5474.19 | F22: 26298.73 | G22: 2937.04 | M22: 115648.32 | N22: 1288.06 | O22: =SUM(C22:N22)*-1 -> -140697.96
A23: 120185 | B23: VEÍCULOS | F23: 0 | O23: =SUM(C23:N23)*-1 -> 0
A24: 122200 | B24: OBRAS DE ARTE | F24: 0 | O24: =SUM(C24:N24)*-1 -> 0
A25: 123505 | B25: MATERIAL DE SERVIÇO | F25: 0 | O25: =SUM(C25:N25)*-1 -> 0
A26: 123510 | B26: VIDROS E CRISTAIS | F26: 0 | O26: =SUM(C26:N26)*-1 -> 0
A27: 123515 | B27: LOUÇAS E PORCELANAS | F27: 0 | O27: =SUM(C27:N27)*-1 -> 0
A28: 123520 | B28: PRATARIA E INOX | F28: 0 | O28: =SUM(C28:N28)*-1 -> 0
A29: 123525 | B29: CONFECCÇÕES PARA CAMA | F29: 0 | O29: =SUM(C29:N29)*-1 -> 0
A30: 123530 | B30: MATERIAL SERVICO CSC PARTICIPANTES. | C30: -1.77 | F30: 2486.91 | N30: 2.08 | O30: =SUM(C30:N30)*-1 -> -2487.22
A31: 123535 | B31: VIDROS E CRISTAIS CSC PARTICIPANTES. | C31: -1.33 | F31: 0 | N31: 1.58 | O31: =SUM(C31:N31)*-1 -> -0.25
A32: 123540 | B32: LOUCAS E PORCELANA CSC PARTICIPANTE. | C32: -5.95 | F32: 8464.11 | N32: 7.01 | O32: =SUM(C32:N32)*-1 -> -8465.17
A33: 123545 | B33: PRATARIA E INOX - CSC PARTICIPANTES. | C33: -1.56 | F33: 4774.74 | N33: 1.84 | O33: =SUM(C33:N33)*-1 -> -4775.02
A35: 124210 | B35: DEPRECIAÇÃO ACUMULADAS | O35: =SUM(O36:O52) -> -1890.67
A36: 124225 | B36: EDIFICAÇÕES | O36: =SUM(C36:N36) -> 0
A37: 124230 | B37: INSTALAÇÕES | O37: =SUM(C37:N37) -> 0
A38: 124231 | B38: INSTALAÇÕES - CSC HTSP | O38: =SUM(C38:N38) -> 0
A39: 124232 | B39: INSTALAÇÕES - CSC PARTICIPANTES | C39: 556.92 | O39: =SUM(C39:N39)*-1 -> -556.92
A40: 124235 | B40: MÁQUINAS E EQUIPAMENTOS | O40: =SUM(C40:N40) -> 0
A41: 124237 | B41: MÁQUINAS E EQUIPAMENTOS - PARTICIPANTES | C41: 76.62 | O41: =SUM(C41:N41)*-1 -> -76.62
A42: 124255 | B42: EQUIPAMENTO PROC. DADOS | O42: =SUM(C42:N42) -> 0
A43: 124256 | B43: EQUIPAMENTO PROC. DADOS - CSC HTSP | O43: =SUM(C43:N43) -> 0
A44: 124257 | B44: EQUIPAMENTO PROC. DADOS - CSC PARTICIPANTES | C44: 892.92 | O44: =SUM(C44:N44)*-1 -> -892.92
...

Sheet tranf. proj
A2: MOVIMENTAÇÃO PATRIMONIAL HTSP - DEZEMBRO 2020
A4: PLANO CONTA | B4: DESCRIÇÃO | C4: 43831 | D4: 43862 | E4: 43891 | F4: 43922 | G4: 43952 | H4: 43983 | I4: 44013 | J4: 44044 | K4: 44075 | L4: 44105 | M4: 44136 | N4: 44166 | O4: TOTAL 2020
C5: 0 | D5: 275042.88 | M5: 468619.71 | N5: =SUM(N7:N26) -> 405324.78 | O5: =SUM(C5:N5)+O55 -> 1149400.3
A6: 116085 | B6: EDIFICAÇÕES | C6: 0 | O6: =SUM(C6:N6) -> 0
A7: 116090 | B7: INSTALAÇÕES | C7: 0 | D7: 163058.56 | M7: 234672.31 | N7: =68846.72+5285.16+5850+926.4+53877.03+7218.32+134702.33+25175.94 -> 301881.9 | O7: =SUM(C7:N7) -> 699612.77
A8: 116095 | B8: INSTALAÇÕES - CSC HTSP | C8: 0 | O8: =SUM(C8:N8) -> 0
A9: 116097 | B9: INSTALAÇÕES - CSC PARTICIPANTES | C9: 0 | O9: =SUM(C9:N9) -> 0
A10: 117095 | B10: SIST. COMUNICAÇÕES | C10: 0 | O10: =SUM(C10:N10) -> 0
A11: 118110 | B11: MÁQUINAS E EQUIPAMENTOS | C11: 0 | D11: 64765.79 | M11: 17856.05 | N11: =565.25+7560 -> 8125.25 | O11: =SUM(C11:N11) -> 90747.09
A12: 118115 | B12: MÁQUINAS E EQUIPAMENTOS - CSC HTSP | C12: 0 | O12: =SUM(C12:N12) -> 0
A13: 118135 | B13: EQUIPAMENTO PROC. DADOS | C13: 0 | M13: 102341.15 | N13: 17675 | O13: =SUM(C13:N13) -> 120016.15
A14: 118140 | B14: EQUIPAMENTO PROC. DADOS - ARREDAMENTO MERCANTIL | C14: 0 | O14: =SUM(C14:N14) -> 0
A15: 118150 | B15: EQUIPAMENTO PROC. DADOS - CSC HTSP | C15: 0 | O15: =SUM(C15:N15) -> 0
A16: 118155 | B16: EQUIPAMENTO PROC. DADOS - CSC PARTICIPANTES | C16: 0 | O16: =SUM(C16:N16) -> 0
A17: 119155 | B17: MÓVEIS E UTENSÍLIOS | D17: 29549.13 | M17: 113750.2 | N17: =46159.75+19008+9180.88 -> 74348.63 | O17: =SUM(C17:N17) -> 217647.96
A18: 119160 | B18: MÓVEIS E UTENSÍLIOS - CSC HTSP | O18: =SUM(C18:N18) -> 0
A19: 119162 | B19: MÓVEIS E UTENSÍLIOS - CSC PARTICIPANTES | O19: =SUM(C19:N19) -> 0
A20: 120185 | B20: VEÍCULOS | O20: =SUM(C20:N20) -> 0
A21: 122200 | B21: OBRAS DE ARTE | O21: =SUM(C21:N21) -> 0
A22: 123505 | B22: MATERIAL DE SERVIÇO | D22: 2794.28 | N22: 3294 | O22: =SUM(C22:N22) -> 6088.28
A23: 123510 | B23: VIDROS E CRISTAIS | O23: =SUM(C23:N23) -> 0
A24: 123515 | B24: LOUÇAS E PORCELANAS | D24: 9510.24 | O24: =SUM(C24:N24) -> 9510.24
A25: 123520 | B25: PRATARIA E INOX | D25: 5364.88 | O25: =SUM(C25:N25) -> 5364.88
A26: 123525 | B26: CONFECCÇÕES PARA CAMA | O26: =SUM(C26:N26) -> 0
A29: 125450 | B29: PROJETOS | D29: 275042.88 | M29: 468619.71 | N29: =SUM(N30:N52) -> 405531.23 | O29: =SUM(C29:N29)*-1 -> -1149193.8
A30: 125497 | B30: PROJETO IMPLANTAÇÃO - ALIMENTOS E BEBIDAS | O30: =SUM(C30:N30) -> 0
A31: 125500 | B31: PROJETO REFORMA DO RESTAURANTE VERBENA | O31: =SUM(C31:N31) -> 0
A32: 125501 | B32: PROJETO REFORMA SALAS DE EVENTOS | N32: =VLOOKUP(A32,'Balancete Contab. 12 2020'!A:F,6,0) -> 72140.72 | O32: =SUM(C32:N32)*-1 -> -72140.72
A33: 125502 | B33: PROJETO REFORMA GERAL APTOS NORTE/SUL | N33: =VLOOKUP(A33,'Balancete Contab. 12 2020'!A:F,6,0) -> 51444.91 | O33: =SUM(C33:N33)*-1 -> -51444.91
A34: 125503 | B34: PROJETO SISTEMA CFTV | N34: =VLOOKUP(A34,'Balancete Contab. 12 2020'!A:F,6,0) -> 6415.25 | O34: =SUM(C34:N34)*-1 -> -6415.25
A35: 125504 | B35: PROJETO REFORMA DE SALAS DA DIRETORIA | N35: =VLOOKUP(A35,'Balancete Contab. 12 2020'!A:F,6,0) -> 19934.4 | O35: =SUM(C35:N35)*-1 -> -19934.4
A36: 125505 | B36: PROJETO RETROFIT ILUMINAÇÃO HTSP | N36: =VLOOKUP(A36,'Balancete Contab. 12 2020'!A:F,6,0) -> 53877.03 | O36: =SUM(C36:N36)*-1 -> -53877.03
A37: 125506 | B37: PROJETO REFORMA CSC | O37: =SUM(C37:N37) -> 0
A38: 125507 | B38: PROJETO REFORMA CSC - FASE 2 | O38: =SUM(C38:N38)*-1 -> 0
A39: 125507 | B39: PROJETO REFORMA CSC - FASE 2 | O39: =SUM(C39:N39)*-1 -> 0
A40: 125508 | B40: PROJETO QUIOSQUE LA BASQUE TEC | O40: =SUM(C40:N40)*-1 -> 0
A41: 125509 | B41: PROJETO REFORMA CSC - FASE 3 | O41: =SUM(C41:N41)*-1 -> 0
A42: 125510 | B42: PROJETO REFORMA CSC - FASE 4. | O42: =SUM(C42:N42)*-1 -> 0
A43: 125511 | B43: PROJETO REFORMA AMPLIACAO FASE 1. | O43: =SUM(C43:N43)*-1 -> 0
A44: 125512 | B44: PROJETO AMPLIACAO REFEITORIO. | D44: 231443.01 | O44: =SUM(C44:N44)*-1 -> -231443.01
...

Sheet baixas
A2: MOVIMENTAÇÃO PATRIMONIAL HTSP - DEZEMBRO 2020
A4: PLANO CONTA | B4: DESCRIÇÃO | C4: 43831 | D4: 43862 | E4: 43891 | F4: 43922 | G4: 43952 | H4: 43983 | I4: 44013 | J4: 44044 | K4: 44075 | L4: 44105 | M4: 44136 | N4: 44166 | O4: TOTAL 2020
O5: =O6+O62 -> 0
O6: =O7-O31+O52 -> 0
O7: =SUM(C7:N7) -> 0
A8: 116085 | B8: EDIFICAÇÕES | O8: =SUM(C8:N8) -> 0
A9: 116090 | B9: INSTALAÇÕES | O9: =SUM(C9:N9) -> 0
A10: 116095 | B10: INSTALAÇÕES - CSC HTSP | O10: =SUM(C10:N10) -> 0
A11: 116097 | B11: INSTALAÇÕES - CSC PARTICIPANTES | O11: =SUM(C11:N11) -> 0
A12: 117095 | B12: SIST. COMUNICAÇÕES | O12: =SUM(C12:N12) -> 0
A13: 118110 | B13: MÁQUINAS E EQUIPAMENTOS | D13: 8391.41 | M13: 0.01 | O13: =SUM(C13:N13) -> 8391.42
A14: 118115 | B14: MÁQUINAS E EQUIPAMENTOS - CSC HTSP | O14: =SUM(C14:N14) -> 0
A15: 118135 | B15: EQUIPAMENTO PROC. DADOS | D15: 62454.96 | O15: =SUM(C15:N15) -> 62454.96
A16: 118140 | B16: EQUIPAMENTO PROC. DADOS - ARREDAMENTO MERCANTIL | O16: =SUM(C16:N16) -> 0
A17: 118150 | B17: EQUIPAMENTO PROC. DADOS - CSC HTSP | O17: =SUM(C17:N17) -> 0
A18: 118155 | B18: EQUIPAMENTO PROC. DADOS - CSC PARTICIPANTES | O18: =SUM(C18:N18) -> 0
A19: 119155 | B19: MÓVEIS E UTENSÍLIOS | D19: 17882.39 | E19: 236.8 | M19: 0.01 | O19: =SUM(C19:N19) -> 18119.2
A20: 119160 | B20: MÓVEIS E UTENSÍLIOS - CSC HTSP | O20: =SUM(C20:N20) -> 0
A21: 119162 | B21: MÓVEIS E UTENSÍLIOS - CSC PARTICIPANTES | O21: =SUM(C21:N21) -> 0
A22: 120185 | B22: VEÍCULOS | O22: =SUM(C22:N22) -> 0
A23: 122200 | B23: OBRAS DE ARTE | O23: =SUM(C23:N23) -> 0
A24: 123505 | B24: MATERIAL DE SERVIÇO | O24: =SUM(C24:N24) -> 0
A25: 123510 | B25: VIDROS E CRISTAIS | O25: =SUM(C25:N25) -> 0
A26: 123515 | B26: LOUÇAS E PORCELANAS | O26: =SUM(C26:N26) -> 0
A27: 123520 | B27: PRATARIA E INOX | O27: =SUM(C27:N27) -> 0
A28: 123525 | B28: CONFECCÇÕES PARA CAMA | O28: =SUM(C28:N28) -> 0
A31: 124210 | B31: (-) DEPRECIACOES ACUMULADAS.......... | O31: =SUM(C31:N31) -> 0
A32: 124225 | B32: (-) EDIFICACOES. | O32: =SUM(C32:N32) -> 0
A33: 124230 | B33: (-) INSTALACOES. | O33: =SUM(C33:N33) -> 0
A34: 124231 | B34: (-) INSTALACOES - CSC HTSP. | O34: =SUM(C34:N34) -> 0
A35: 124235 | B35: (-) MAQUINAS E EQUIPAMENTOS. | D35: 7910.07 | M35: 0.01 | O35: =SUM(C35:N35) -> 7910.08
A36: 124236 | B36: (-) MAQUINAS E EQUIPAMENTOS - CSC HTSP. | O36: =SUM(C36:N36) -> 0
A37: 124255 | B37: (-) EQUIP. PROC. DE DADOS. | D37: 58232.47 | M37: 0 | O37: =SUM(C37:N37) -> 58232.47
A38: 124256 | B38: (-) EQUIP. PROC. DE DADOS - CSC HTSP. | O38: =SUM(C38:N38) -> 0
A39: 124257 | B39: (-) EQUIP. PROC. DE DADOS - CSC PARTIC.. | O39: =SUM(C39:N39) -> 0
A40: 124270 | B40: (-) MOVEIS UTENS. HOSP. | D40: 16365.24 | M40: 0.01 | O40: =SUM(C40:N40) -> 16365.25
A41: 124275 | B41: (-) MOVEIS E UTENSILIOS - CSC HTSP. | O41: =SUM(C41:N41) -> 0
A42: 124276 | B42: (-) MOVEIS E UTENSILIOS - CSC PARTIC.. | O42: =SUM(C42:N42) -> 0
A43: 124300 | B43: (-) VEICULOS. | O43: =SUM(C43:N43) -> 0
A44: 124305 | B44: (-) MATERIAL DE SERVICOS. | O44: =SUM(C44:N44) -> 0
...

Sheet depreciações
A2: MOVIMENTAÇÃO PATRIMONIAL HTSP - DEZEMBRO 2020
A4: PLANO CONTA | B4: DESCRIÇÃO | C4: 43831 | E4: 43891 | F4: 43922 | G4: 43952 | H4: 43983 | I4: 44013 | J4: 44044 | K4: 44075 | L4: 44105 | M4: 44136 | N4: 44166 | O4: TOTAL 2020
O5: =SUM(O7+O38+O42)*-1 -> -9500236.5
A7: 124210 | B7: (-) DEPRECIACOES ACUMULADAS.......... | C7: =SUM(C8:C36) -> 312044.22 | D7: =SUM(D8:D36) -> 311988 | E7: =SUM(E8:E36) -> 314709.21 | F7: =SUM(F8:F36) -> 313651.9 | G7: =SUM(G8:G36) -> 310846.03 | H7: =SUM(H8:H36) -> 311931.18 | I7: 311893.62 | J7: 312065.34 | K7: 312071.91 | L7: 310169.57 | M7: 309033.43 | N7: =SUM(N8:N36) -> 309375.23 | O7: =SUM(O8:O35) -> 3739779.6
A8: 124225 | B8: (-) EDIFICACOES. | C8: 26825.04 | D8: 26797.77 | E8: 26797.62 | F8: 26739.04 | G8: 26738.71 | H8: 26708.1 | I8: 26677.58 | J8: 26677.28 | K8: 26672.96 | L8: 26673.11 | M8: 26557.59 | N8: =VLOOKUP(A8,'Balancete Contab. 12 2020'!A:F,6,0) -> 26411.56 | O8: =SUM(C8:N8) -> 320276.36
A9: 124230 | B9: (-) INSTALACOES. | C9: 174391.74 | D9: 174324.97 | E9: 174083.01 | F9: 174016.13 | G9: 174015.7 | H9: 174015.78 | I9: 174015.78 | J9: 174016.52 | K9: 174014.99 | L9: 173990.08 | M9: 173518.24 | N9: =VLOOKUP(A9,'Balancete Contab. 12 2020'!A:F,6,0) -> 175648.74 | O9: =SUM(C9:N9) -> 2090051.7
A10: 124231 | B10: (-) INSTALACOES - CSC HTSP. | C10: 4026.63 | D10: 4026.65 | E10: 5385.38 | F10: 5385.45 | G10: 5385.5 | H10: 5385.42 | I10: 5385.48 | J10: 5385.46 | K10: 5385.45 | L10: 5410.44 | M10: 5445.07 | N10: =VLOOKUP(A10,'Balancete Contab. 12 2020'!A:F,6,0) -> 5445.02 | O10: =SUM(C10:N10) -> 62051.95
A11: 124232 | B11: (-) INSTALACOES - CSC PARTIC.. | C11: -3453.66 | D11: -3428.59 | E11: -3428.58 | F11: -3458.19 | G11: -5876.93 | H11: -4667.51 | I11: -4667.56 | J11: -4667.54 | K11: -4667.53 | L11: -4689.07 | M11: -4718.91 | N11: =-VLOOKUP(A11,'Balancete Contab. 12 2020'!A:F,5,0) -> -6674.4 | O11: =SUM(C11:N11) -> -54398.47
A12: 124235 | B12: (-) MAQUINAS E EQUIPAMENTOS. | C12: 16780.75 | D12: 16762.23 | E12: 16859.39 | F12: 17008.64 | G12: 16973.17 | H12: 16972.12 | I12: 16973.33 | J12: 17302.16 | K12: 17403.3 | L12: 17766.96 | M12: 17746.4 | N12: =VLOOKUP(A12,'Balancete Contab. 12 2020'!A:F,6,0) -> 17845.96 | O12: =SUM(C12:N12) -> 206394.41
A13: 124236 | B13: (-) MAQUINAS E EQUIPAMENTOS - CSC HTSP. | C13: 379.33 | D13: 379.3 | E13: 919.1 | F13: 919.03 | G13: 919.07 | H13: 919.02 | I13: 919.03 | J13: 919.03 | K13: 919.14 | L13: 919.1 | M13: 919.09 | N13: =VLOOKUP(A13,'Balancete Contab. 12 2020'!A:F,6,0) -> 919.02 | O13: =SUM(C13:N13) -> 9949.26
A14: 124237 | B14: (-) MAQUINAS E EQUIPAMENTOS CSC PARTIC.. | C14: -317.83 | D14: -317.38 | E14: -317.48 | F14: -798.24 | G14: -798.27 | H14: -798.23 | I14: -798.24 | J14: -798.24 | K14: -798.33 | L14: -798.31 | M14: -798.29 | N14: =-VLOOKUP(A14,'Balancete Contab. 12 2020'!A:F,5,0) -> -947.03 | O14: =SUM(C14:N14) -> -8285.87
A15: 124255 | B15: (-) EQUIP. PROC. DE DADOS. | C15: 9691.19 | D15: 9715.49 | E15: 9861.08 | F15: 9545.31 | G15: 9269.99 | H15: 9216.74 | I15: 9216.78 | J15: 8998.61 | K15: 9159.91 | L15: 9159.91 | M15: 9199.43 | N15: =VLOOKUP(A15,'Balancete Contab. 12 2020'!A:F,6,0) -> 10938.48 | O15: =SUM(C15:N15) -> 113972.92
A16: 124256 | B16: (-) EQUIP. PROC. DE DADOS - CSC HTSP. | C16: 5616.84 | D16: 5755.41 | E16: 5475.81 | F16: 5702.26 | G16: 5702.17 | H16: 5755 | I16: 5755.41 | J16: 5971.61 | K16: 5754.98 | L16: 5755.38 | M16: 5755.43 | N16: =VLOOKUP(A16,'Balancete Contab. 12 2020'!A:F,6,0) -> 5951.29 | O16: =SUM(C16:N16) -> 68951.59
A17: 124257 | B17: (-) EQUIP. PROC. DE DADOS - CSC PARTIC.. | C17: -4675 | D17: -4881.36 | E17: -4881 | F17: -4868.54 | G17: -4868.42 | H17: -4915.46 | I17: -4915.84 | J17: -5108.22 | K17: -4915.44 | L17: -4915.81 | M17: -4915.82 | N17: =-VLOOKUP(A17,'Balancete Contab. 12 2020'!A:F,5,0) -> -6784.37 | O17: =SUM(C17:N17) -> -60645.28
A18: 124260 | B18: (-) EQUIP.PROCE.DADOS-ARREND.MERCANTIL. | C18: 4157.43 | D18: 4157.28 | E18: 4157.37 | F18: 4157.29 | G18: 4157.1 | H18: 4157.45 | I18: 4157.26 | J18: 4157.44 | K18: 4157.21 | L18: 4157.45 | M18: 4157.26 | N18: =VLOOKUP(A18,'Balancete Contab. 12 2020'!A:F,6,0) -> 4157.29 | O18: =SUM(C18:N18) -> 49887.83
A19: 124270 | B19: (-) MOVEIS UTENS. HOSP. | C19: 59036.72 | D19: 59091.49 | E19: 59653.3 | F19: 59665.01 | G19: 59589.22 | H19: 59544.2 | I19: 59535.97 | J19: 59572.43 | K19: 59346.31 | L19: 57103.23 | M19: 56528.25 | N19: =VLOOKUP(A19,'Balancete Contab. 12 2020'!A:F,6,0) -> 57767.21 | O19: =SUM(C19:N19) -> 706433.34
A20: 124275 | B20: (-) MOVEIS E UTENSILIOS - CSC HTSP. | C20: 2850.48 | D20: 2852.21 | E20: 3093.58 | F20: 3093.62 | G20: 3093.97 | H20: 3094.22 | I20: 3092.87 | J20: 3094.72 | K20: 3094.01 | L20: 3093.21 | M20: 3101.24 | N20: =VLOOKUP(A20,'Balancete Contab. 12 2020'!A:F,6,0) -> 3124.41 | O20: =SUM(C20:N20) -> 36678.54
A21: 124276 | B21: (-) MOVEIS E UTENSILIOS - CSC PARTIC.. | C21: -2456.44 | D21: -2437.17 | E21: -2433.45 | F21: -2676.75 | G21: -2677.08 | H21: -2677.26 | I21: -2676.12 | J21: -2677.69 | K21: -2677.1 | L21: -2676.39 | M21: -2683.15 | N21: =-VLOOKUP(A21,'Balancete Contab. 12 2020'!A:F,5,0) -> -3649.99 | O21: =SUM(C21:N21) -> -32398.59
A22: 124300 | B22: (-) VEICULOS. | C22: 0 | D22: 0 | E22: 0 | F22: 0 | G22: 0 | H22: 0 | I22: 0 | J22: 0 | K22: 0 | L22: 0 | M22: 0 | N22: =VLOOKUP(A22,'Balancete Contab. 12 2020'!A:F,6,0) -> 0 | O22: =SUM(C22:N22) -> 0
A23: 124305 | B23: (-) MATERIAL DE SERVICOS. | C23: 9806.95 | D23: 9806.96 | E23: 9806.94 | F23: 9806.96 | G23: 9807.05 | H23: 9806.93 | I23: 9806.98 | J23: 9806.93 | K23: 9806.99 | L23: 9807.03 | M23: 9806.93 | N23: =VLOOKUP(A23,'Balancete Contab. 12 2020'!A:F,6,0) -> 9806.96 | O23: =SUM(C23:N23) -> 117683.61
A24: 124306 | B24: (-) MATERIAL DE SERVICO - CSC HTSP. | C24: 2.12 | D24: 2.12 | E24: 48.68 | F24: 48.69 | G24: 48.69 | H24: 48.7 | I24: 48.69 | J24: 48.68 | K24: 48.7 | L24: 48.69 | M24: 48.69 | N24: =VLOOKUP(A24,'Balancete Contab. 12 2020'!A:F,6,0) -> 48.7 | O24: =SUM(C24:N24) -> 491.15
A25: 124308 | B25: (-) MATERIAL DE SERVICO CSC PARTIC.. | C25: -1.88 | D25: -1.85 | E25: -1.85 | F25: -43.34 | G25: -43.34 | H25: -43.35 | I25: -43.34 | J25: -43.33 | K25: -43.35 | L25: -43.34 | M25: -43.34 | N25: =-VLOOKUP(A25,'Balancete Contab. 12 2020'!A:F,5,0) -> -43.35 | O25: =SUM(C25:N25) -> -395.66
A26: 124316 | B26: (-) VIDROS E CRISTAIS - CSC HTSP. | C26: 1.6 | D26: 1.6 | E26: 1.6 | F26: 1.6 | G26: 1.6 | H26: 1.6 | I26: 1.6 | J26: 1.6 | K26: 1.6 | L26: 1.6 | M26: 1.6 | N26: =VLOOKUP(A26,'Balancete Contab. 12 2020'!A:F,6,0) -> 1.6 | O26: =SUM(C26:N26) -> 19.2
A27: 124318 | B27: (-) VIDROS E CRISTAIS CSC PARTIC.. | C27: -1.42 | D27: -1.4 | E27: -1.4 | F27: -1.42 | G27: -1.42 | H27: -1.42 | I27: -1.42 | J27: -1.42 | K27: -1.42 | L27: -1.42 | M27: -1.42 | N27: =-VLOOKUP(A27,'Balancete Contab. 12 2020'!A:F,5,0) -> -1.42 | O27: =SUM(C27:N27) -> -17
A28: 124321 | B28: (-) LOUCAS E PORCELANAS - CSC HTSP. | C28: 7.13 | D28: 7.14 | E28: 165.62 | F28: 165.63 | G28: 165.64 | H28: 165.64 | I28: 165.64 | J28: 165.62 | K28: 165.64 | L28: 165.64 | M28: 165.63 | N28: =VLOOKUP(A28,'Balancete Contab. 12 2020'!A:F,6,0) -> 165.65 | O28: =SUM(C28:N28) -> 1670.62
A29: 124323 | B29: (-) LOUCAS E PORCELANAS CSC PARTIC.. | C29: -6.33 | D29: -6.24 | E29: -6.22 | F29: -147.42 | G29: -147.42 | H29: -147.42 | I29: -147.42 | J29: -147.41 | K29: -147.42 | L29: -147.42 | M29: -147.42 | N29: =-VLOOKUP(A29,'Balancete Contab. 12 2020'!A:F,5,0) -> -147.42 | O29: =SUM(C29:N29) -> -1345.56
A30: 124326 | B30: (-) PRATARIA E INOX - CSC HTSP. | C30: 1.88 | D30: 1.87 | E30: 91.24 | F30: 91.31 | G30: 91.25 | H30: 91.3 | I30: 91.28 | J30: 91.28 | K30: 91.27 | L30: 91.31 | M30: 91.25 | N30: =VLOOKUP(A30,'Balancete Contab. 12 2020'!A:F,6,0) -> 91.3 | O30: =SUM(C30:N30) -> 916.54
A31: 124328 | B31: (-) PRATARIA E INOX CSC PARTIC.. | C31: -1.67 | D31: -1.63 | E31: -1.62 | F31: -81.26 | G31: -81.22 | H31: -81.25 | I31: -81.24 | J31: -81.24 | K31: -81.23 | L31: -81.26 | M31: -81.22 | N31: =-VLOOKUP(A31,'Balancete Contab. 12 2020'!A:F,5,0) -> -81.25 | O31: =SUM(C31:N31) -> -736.09
A33: 124315 | B33: (-) VIDROS E CRISTAIS. | C33: 1039.81 | D33: 1038.18 | E33: 1038.19 | F33: 1038.21 | G33: 1038.15 | H33: 1038.18 | I33: 1038.22 | J33: 1038.19 | K33: 1038.19 | L33: 1036.58 | M33: 1038.2 | N33: =VLOOKUP(A33,'Balancete Contab. 12 2020'!A:F,6,0) -> 1038.22 | O33: =SUM(C33:N33) -> 12458.32
A34: 124320 | B34: (-) LOUCAS E PORCELANAS. | C34: 5158.72 | D34: 5158.8 | E34: 5158.77 | F34: 5158.74 | G34: 5158.94 | H34: 5158.59 | I34: 5158.8 | J34: 5158.71 | K34: 5158.89 | L34: 5158.74 | M34: 5158.67 | N34: =VLOOKUP(A34,'Balancete Contab. 12 2020'!A:F,6,0) -> 5158.82 | O34: =SUM(C34:N34) -> 61905.19
A35: 124325 | B35: (-) PRATARIA E INOX. | C35: 3184.09 | D35: 3184.15 | E35: 3184.13 | F35: 3184.14 | G35: 3184.21 | H35: 3184.09 | I35: 3184.1 | J35: 3184.16 | K35: 3184.19 | L35: 3184.13 | M35: 3184.03 | N35: =VLOOKUP(A35,'Balancete Contab. 12 2020'!A:F,6,0) -> 3184.23 | O35: =SUM(C35:N35) -> 38209.65
A36: 124330 | B36: (-) CONFECCOES PARA CAMA. | C36: 0 | D36: 0 | E36: 0 | F36: 0 | G36: 0 | H36: 0 | I36: 0 | J36: 0 | K36: 0 | L36: 0 | M36: 0 | N36: =VLOOKUP(A36,'Balancete Contab. 12 2020'!A:F,6,0) -> 0 | O36: =SUM(C36:N36) -> 0
A38: 124810 | B38: (-) AMORTIZACAO ACUMULADA............ | C38: 488504.52 | D38: 488504.45 | E38: 488504.49 | F38: 488504.52 | G38: 488504.5 | H38: 488504.49 | I38: 488504.49 | J38: 481122.95 | K38: 481122.97 | L38: 481122.98 | M38: 469511.51 | N38: =VLOOKUP(A38,'Balancete Contab. 12 2020'!A:F,6,0) -> 469511.55 | O38: =SUM(C38:N38) -> 5801923.4
A39: 124820 | B39: BENFEITORIAS EM IMOVEIS DE TERCEIRO. - QUIOSQUE LA BASQUE | C39: 5275.57 | D39: 5275.5 | E39: 5275.54 | F39: 5275.57 | G39: 5275.53 | H39: 5275.54 | I39: 5275.54 | J39: 5275.53 | K39: 5275.55 | L39: 5275.56 | M39: 5275.5 | N39: =VLOOKUP(A39,'Balancete Contab. 12 2020'!A:F,6,0) -> 5275.54 | O39: =SUM(C39:N39) -> 63306.47
A40: 124890 | B40: DIREITO DE USO | C40: 483228.95 | D40: 483228.95 | E40: 483228.95 | F40: 483228.95 | G40: 483228.97 | H40: 483228.95 | I40: 483228.95 | J40: 475847.42 | K40: 475847.42 | L40: 475847.42 | M40: 464236.01 | N40: =VLOOKUP(A40,'Balancete Contab. 12 2020'!A:F,6,0) -> 464236.01 | O40: =SUM(C40:N40) -> 5738617
A42: 135000 | B42: (-)DEPREC. ACUM.AJUSTE CPC27......... | C42: 936.75 | D42: =SUM(D43:D53) -> 1554.92 | E42: =SUM(E43:E53) -> -139.91 | F42: =SUM(F43:F53) -> -1762.95 | G42: =SUM(G43:G53) -> -2695.02 | H42: =SUM(H43:H53) -> -4147.67 | I42: -5181.88 | J42: -5990.0202 | K42: -6790.82 | L42: -5946.79 | M42: -4873.01 | N42: =SUM(N43:N53) -> -6430.17 | O42: =SUM(O43:O53) -> -41466.57
A43: 135005 | B43: (-) EDIFICACOES. | C43: -26825.04 | D43: -26797.77 | E43: -26797.62 | F43: -26739.04 | G43: -26738.71 | H43: -26708.1 | I43: -26677.58 | J43: -26677.28 | K43: -26672.96 | L43: -26673.11 | M43: -26557.59 | N43: =VLOOKUP(A43,'Ativo CPC 27 12 20'!A:H,8,0) -> -26411.56 | O43: =SUM(C43:N43) -> -320276.36
A44: 135010 | B44: (-) INSTALACOES. | C44: 0 | D44: 0 | E44: 0 | F44: 0 | G44: 0 | H44: 0 | I44: 0 | J44: 0 | K44: 0 | L44: 0 | M44: 0 | N44: =VLOOKUP(A44,'Ativo CPC 27 12 20'!A:H,8,0) -> 0 | O44: =SUM(C44:N44) -> 0
A45: 135015 | B45: (-) MAQUINAS E EQUIPAMENTOS. | C45: 3711.05 | D45: 4373.04 | E45: 4119.13 | F45: 3528.3 | G45: 3371.21 | H45: 3190.48 | I45: 2985.25 | J45: 3091.82 | K45: 3456.3 | L45: 2909.19 | M45: 2716.45 | N45: =VLOOKUP(A45,'Ativo CPC 27 12 20'!A:H,8,0) -> 2532.29 | O45: =SUM(C45:N45) -> 39984.51
A46: 135020 | B46: (-) EQUIP. PROC. DE DADOS. | C46: 12222.08 | D46: 11404.63 | E46: 11493.4 | F46: 11359.98 | G46: 11416.3 | H46: 10952.84 | I46: 10982.62 | J46: 10915.03 | K46: 10494.63 | L46: 10190.13 | M46: 10117.26 | N46: =VLOOKUP(A46,'Ativo CPC 27 12 20'!A:H,8,0) -> 9826.02 | O46: =SUM(C46:N46) -> 131374.92
...

Sheet Balancete Contab. 12 2020
A1: CIA. TRAN | B1: SAMERICA DE HOTEIS - SAO PAULO | G1: [ HTSP ]
A2: BALANCETE | B2: MENSAL | G2: Pag. 1
A3: EMPRESA | D3: Referente: 2020-12 | G3: [ rlctb001 ]
A4: CONTA | B4: ATIVO | C4: NIV | D4: SALDO ANTERIOR | E4: DEBITOS | F4: CREDITOS | G4: SALDO ATUAL
A5: 1000 | B5: ATIVO.................................... | C5: 1 | D5: 55259950 | E5: 21439906 | F5: 23986102 | G5: 52713753
A6: 2000 | B6: ATIVO CIRCULANTE........................ | C6: 2 | D6: 17687371 | E6: 20711275 | F6: 22497173 | G6: 15901473
A7: 3000 | B7: DISPONIVEL............................. | C7: 3 | D7: 9302985.1 | E7: 13958532 | F7: 15684881 | G7: 7576636.6
A8: 4000 | B8: CAIXA FUNDO FIXO...................... | C8: 4 | D8: 19700 | E8: 0 | F8: 0 | G8: 19700
A9: 4005 | B9: CAIXA FUNDO FIXO-TESOURARIA GERAL. | C9: 5 | D9: 8500 | E9: 0 | F9: 0 | G9: 8500
A10: 4020 | B10: CAIXA FUNDO FIXO - COMPRAS/SP. | C10: 5 | D10: 4500 | E10: 0 | F10: 0 | G10: 4500
A11: 4030 | B11: CAIXA FUNDO FIXO - RECEPCAO. | C11: 5 | D11: 5000 | E11: 0 | F11: 0 | G11: 5000
A12: 4035 | B12: CAIXA FUNDO FIXO - P.D.V. | C12: 5 | D12: 1500 | E12: 0 | F12: 0 | G12: 1500
A13: 4041 | B13: CAIXA FUNDO FIXO - LA BASQUE. | C13: 5 | D13: 200 | E13: 0 | F13: 0 | G13: 200
A14: 5040 | B14: CAIXA GERAL OPERACIONAL. | C14: 4 | D14: 59663.59 | E14: 20741.87 | F14: 45254.18 | G14: 35151.28
A15: 6040 | B15: BANCOS CONTA MOVIMENTO................ | C15: 4 | D15: 10846.59 | E15: 10333760 | F15: 10317267 | G15: 27340.3
A16: 6045 | B16: BANCO SANTANDER-AG. CORPORATE(0689). | C16: 5 | D16: 0 | E16: 5788122.9 | F16: 5780291.9 | G16: 7831
... A1221: 900000 | B1221: R E S U L T A D O........................ | C1221: 1 | D1221: -24900488 | E1221: 7598317.7 | F1221: 5763912.8 | G1221: -26734893

Sheet Afixo  Saldos Geral  htsp 12 20
A1: CIA. TRANSAMERICA DE HOTEIS - SAO PAULO [ HTSP ]
A2: Relatório Valores do Ativo Imobilizado (Saldos (Geral)) Período: 12/2020 Pag. 1
A3: [ Controle de ativo fixo ] [ rlafx005 ]
A4: Conta | B4: Grupos/Especies | C4: Qtd. Itens | D4: Valor | E4: Correcao | F4: Valor | G4: Depreciacao | H4: Depreciacao | I4: Valor | J4: Correcao | K4: Depreciacao | L4: Residual
D5: Original | E5: Acumulada | F5: Acumulado | G5: Mes | H5: Acumulada | I5: Residual | J5: 8200 | K5: 8200 | L5: 8200
B6: DIFERIDO | C6: 924 | D6: 2638432.1 | E6: 0 | F6: 2638432.1 | G6: 16129.39 | H6: 1671891.2 | I6: 966540.82 | J6: 0 | K6: 0 | L6: 0
A7: 124110 | B7: PROJETO QUIOSQUE LA BASQUE TEC | C7: 29 | D7: 94959.72 | E7: 0 | F7: 94959.72 | G7: 5275.54 | H7: 79132.94 | I7: 15826.78 | J7: 0 | K7: 0 | L7: 0
A8: 124820 | B8: PROJETO REFORMA CSC - ALFA | C8: 79 | D8: 919939.93 | E8: 0 | F8: 919939.93 | G8: 7610.33 | H8: 93929.28 | I8: 826010.65 | J8: 0 | K8: 0 | L8: 0
A9: 145310 | B9: SOFTWARE APARTIR 2009 | C9: 90 | D9: 509509.07 | E9: 0 | F9: 509509.07 | G9: 3243.52 | H9: 384805.68 | I9: 124703.39 | J9: 0 | K9: 0 | L9: 0
A10: - | B10: SOFTWARE ATE 2008 | C10: 726 | D10: 1114023.4 | E10: 0 | F10: 1114023.4 | G10: 0 | H10: 1114023.4 | I10: 0 | J10: 0 | K10: 0 | L10: 0
A12: 124225 | B12: EDIFICACAO | C12: 751 | D12: 19903245 | E12: 21876126 | F12: 41779372 | G12: 26411.56 | H12: 40596453 | I12: 1182918.9 | J12: 18823804 | K12: 18823804 | L12: 0.01
B13: EDIFICACAO TORRE NORTE | C13: 158 | D13: 11696107 | E13: 2217204.2 | F13: 13913311 | G13: 7158.37 | H13: 13795217 | I13: 118094.29 | J13: 8388849.5 | K13: 8388849.5 | L13: 0
B14: EDIFICACAO TORRE SUL | C14: 344 | D14: 3513574.5 | E14: 19617903 | F14: 23131478 | G14: 5082.16 | H14: 23034534 | I14: 96943.76 | J14: 10434955 | K14: 10434955 | L14: 0.01
B15: HELIPONTO | C15: 5 | D15: 160330 | E15: 0 | F15: 160330 | G15: 534.43 | H15: 123721.21 | I15: 36608.79 | J15: 0 | K15: 0 | L15: 0
B16: PASSARELA | C16: 1 | D16: 356732.68 | E16: 0 | F16: 356732.68 | G16: 0 | H16: 356732.68 | I16: 0 | J16: 0 | K16: 0 | L16: 0
B17: QUADRAS/PISCINA | C17: 25 | D17: 121849.56 | E17: 41018.6 | F17: 162868.16 | G17: 120.83 | H17: 161640.74 | I17: 1227.42 | J17: 0 | K17: 0 | L17: 0
B18: RESTAURANTE ANTURIUS | C18: 216 | D18: 4052901.8 | E18: 0 | F18: 4052901.8 | G18: 13509.93 | H18: 3123382.1 | I18: 929519.7 | J18: 0 | K18: 0 | L18: 0
B19: SALA VIP TEC/SP/TAM | C19: 2 | D19: 1750 | E19: 0 | F19: 1750 | G19: 5.84 | H19: 1225.04 | I19: 524.96 | J19: 0 | K19: 0 | L19: 0
A21: 124255 | B21: EQUIPAMENTO PROC. DE DADOS | C21: 1978 | D21: 2398909.7 | E21: 0 | F21: 2398909.7 | G21: =21047.11-G100 -> 16889.82 | H21: 1716695 | I21: 682214.7 | J21: 0 | K21: 0 | L21: 0
B22: ACCESS POINT | C22: 131 | D22: 330433.96 | E22: 0 | F22: 330433.96 | G22: 2565.79 | H22: 304776.36 | I22: 25657.6 | J22: 0 | K22: 0 | L22: 0
B23: CELULAR/IPHONE/IPAD | C23: 46 | D23: 65906.81 | E23: 0 | F23: 65906.81 | G23: 920.48 | H23: 47208.33 | I23: 18698.48 | J23: 0 | K23: 0 | L23: 0
B24: CHAVEADOR | C24: 3 | D24: 2685.07 | E24: 0 | F24: 2685.07 | G24: 44.75 | H24: 2011.82 | I24: 673.25 | J24: 0 | K24: 0 | L24: 0
B25: COLETOR DE DADOS | C25: 5 | D25: 9542.01 | E25: 0 | F25: 9542.01 | G25: 67.37 | H25: 8387.67 | I25: 1154.34 | J25: 0 | K25: 0 | L25: 0
B26: CONTROLADOR DE REDE | C26: 1 | D26: 1699.01 | E26: 0 | F26: 1699.01 | G26: 28.32 | H26: 764.55 | I26: 934.46 | J26: 0 | K26: 0 | L26: 0
B27: CONVERSOR SINAL DE VIDEO | C27: 4 | D27: 10000 | E27: 0 | F27: 10000 | G27: 0 | H27: 10000 | I27: 0 | J27: 0 | K27: 0 | L27: 0
B28: EQTO PROCES. DADOS DIVERSOS | C28: 11 | D28: 61375.22 | E28: 0 | F28: 61375.22 | G28: 1003.2 | H28: 18388.31 | I28: 42986.91 | J28: 0 | K28: 0 | L28: 0
B29: EQTO SISTEMA SEGURANCA DE REDE | C29: 5 | D29: 52698.44 | E29: 0 | F29: 52698.44 | G29: 282.36 | H29: 42532.96 | I29: 10165.48 | J29: 0 | K29: 0 | L29: 0
B30: GRAVADOR DE CD | C30: 2 | D30: 1065 | E30: 0 | F30: 1065 | G30: 17.75 | H30: 606.77 | I30: 458.23 | J30: 0 | K30: 0 | L30: 0
B31: IMPRESSORA | C31: 63 | D31: 83835.37 | E31: 0 | F31: 83835.37 | G31: 425.22 | H31: 65813.33 | I31: 18022.04 | J31: 0 | K31: 0 | L31: 0
B32: LEITOR/GRAVADOR CARTAO CREDITO | C32: 15 | D32: 92341.83 | E32: 0 | F32: 92341.83 | G32: 1059.98 | H32: 69984.11 | I32: 22357.72 | J32: 0 | K32: 0 | L32: 0
B33: MICROCOMPUTADOR | C33: 344 | D33: 591913.15 | E33: 0 | F33: 591913.15 | G33: 6642.65 | H33: 340382.51 | I33: 251530.64 | J33: 0 | K33: 0 | L33: 0
... B47: UNIDADE DE BACK-UP | C47: 1 | D47: 8974.28 | E47: 0 | F47: 8974.28 | G47: 149.57 | H47: 6581.13 | I47: 2393.15 | J47: 0 | K47: 0 | L47: 0
A49: 124230 | B49: INSTALACAO | C49: 3793 | D49: 33336308 | E49: 8198721.4 | F49: 41535029 | G49: 173483.43 | H49: 34750262 | I49: 6784767.3 | J49: 4115193.6 | K49: 4115193.6 | L49: 0
B50: INSTALACAO GERAL | C50: 3566 | D50: 30728550 | E50: 8198721.4 | F50: 38927272 | G50: 165341.99 | H50: 32435686 | I50: 6491585.5 | J50: 4115193.6 | K50: 4115193.6 | L50: 0
B51: INSTALACAO HOSPEDAGEM | C51: 227 | D51: 2607757.4 | E51: 0 | F51: 2607757.4 | G51: 8141.44 | H51: 2314575.6 | I51: 293181.8 | J51: 0 | K51: 0 | L51: 0
A53: 124235 | B53: MAQUINA E EQUIPAMENTO | C53: 2087 | D53: 3719973.2 | E53: 396750.03 | F53: 4116723.2 | G53: 18764.97 | H53: 2977690.4 | I53: 1139032.9 | J53: 323555.05 | K53: 323555.05 | L53: 0
B54: GRAMPEADOR INDUSTRIAL | C54: 6 | D54: 864.8 | E54: 0 | F54: 864.8 | G54: 0 | H54: 864.8 | I54: 0 | J54: 0 | K54: 0 | L54: 0
B55: MAQUINA POLIDORA DE SAPATOS | C55: 2 | D55: 1820 | E55: 0 | F55: 1820 | G55: 0 | H55: 1820 | I55: 0 | J55: 0 | K55: 0 | L55: 0
B56: MAQUINAS E EQUIPAMENTOS ADM./O | C56: 1054 | D56: 3355698.5 | E56: 384190.25 | F56: 3739888.7 | G56: 17442.9 | H56: 2701570.8 | I56: 1038317.9 | J56: 315924.48 | K56: 315924.48 | L56: 0
B57: MAQUINAS E EQUIPAMENTOS HOSPED | C57: 454 | D57: 47555.98 | E57: 0 | F57: 47555.98 | G57: 0 | H57: 47555.98 | I57: 0 | J57: 0 | K57: 0 | L57: 0
...

Sheet Afixo Aquisição  12 20 
A1: CIA. TRANSAMERICA DE HOTEIS - SAO PAULO [ HTSP ]
A2: Relatório Valores do Ativo Imobilizado - AQUISICAO Período: 12/2020 Pag. 1
A3: [ Controle de ativo fixo ] [ rlafx002 ]
A4: Conta | B4: Grupos/Especies | C4: Qtd. Itens | D4: Valor | E4: Correção | F4: Valor | G4: Depreciação | H4: Depreciação | I4: Valor | J4: Correção | K4: Depreciação | L4: Residual
D5: Original | E5: Acumulada | F5: Acumulado | G5: Mes | H5: Acumulada | I5: Residual | J5: 8200 | K5: 8200 | L5: 8200
A6: 145310 | B6: SOFTWARE | C6: 2 | D6: 1509 | E6: 0 | F6: 1509 | G6: 15.49 | H6: 15.49 | I6: 1493.51 | J6: 0 | K6: 0 | L6: 0
B7: SOFTWARE APARTIR 2009 | C7: 2 | D7: 1509 | E7: 0 | F7: 1509 | G7: 15.49 | H7: 15.49 | I7: 1493.51 | J7: 0 | K7: 0 | L7: 0
A9: 118135 | B9: EQUIPAMENTO PROC. DE DADOS | C9: 2 | D9: 11556 | E9: 0 | F9: 11556 | G9: 112.79 | H9: 112.79 | I9: 11443.21 | J9: 0 | K9: 0 | L9: 0
B10: NOTEBOOK | C10: 2 | D10: 11556 | E10: 0 | F10: 11556 | G10: 112.79 | H10: 112.79 | I10: 11443.21 | J10: 0 | K10: 0 | L10: 0
B11: Total geral ................................................ | C11: 4 | D11: 13065 | E11: 0 | F11: 13065 | G11: 128.28 | H11: 128.28 | I11: 12936.72 | J11: 0 | K11: 0 | L11: 0
B12: Critério de Seleção: afx_afxbem.cmpprj_cod is null and afx_afxmov.afxmov_dt_mov between '20201201 00:00:00.000' and '20201231 00:00:00.000'
A16: CIA. TRANSAMERICA DE HOTEIS - SAO PAULO [ HTSP ]
A17: Relatório Valores do Ativo Imobilizado - AQUISICAO PROJETOS Período: 12/2020 Pag. 1
A18: [ Controle de ativo fixo ] [ rlafx002 ]
A19: Conta | B19: Grupos/Especies | C19: Qtd. Itens | D19: Valor | E19: Correção | F19: Valor | G19: Depreciação | H19: Depreciação | I19: Valor | J19: Correção | K19: Depreciação | L19: Residual
D20: Original | E20: Acumulada | F20: Acumulado | G20: Mes | H20: Acumulada | I20: Residual | J20: 8200 | K20: 8200 | L20: 8200
B21: INSTALACAO | C21: 2 | D21: 53100 | E21: 0 | F21: 53100 | G21: 0 | H21: 0 | I21: 53100 | J21: 0 | K21: 0 | L21: 0
B22: INSTALACAO GERAL | C22: 2 | D22: 53100 | E22: 0 | F22: 53100 | G22: 0 | H22: 0 | I22: 53100 | J22: 0 | K22: 0 | L22: 0
B23: Total geral ................................................ | C23: 2 | D23: 53100 | E23: 0 | F23: 53100 | G23: 0 | H23: 0 | I23: 53100 | J23: 0 | K23: 0 | L23: 0
B24: Critério de Seleção: afx_afxbem.cmpprj_cod between 1000 and 1143 and afx_afxmov.afxmov_dt_mov between '20201201 00:00:00.000' and '20201231 00:00:00.000'
A27: 125518 | B27: PROJ DR INST. ELETRICA 5-6-7-8 ANDA. | F27: 48100
A28: 125521 | B28: PROJETO BOULANGERIE HT. | F28: 5000
F29: =SUM(F27:F28) -> 53100
A32: 125515 | B32: PROJETO IMPLANTACAO SISTEMA TOTVS. | F32: 19104.7
A33: * Apenas controle contábil

Sheet Afixo Baixas Geral 12 2020

Sheet Ativo CPC 27   12 20
A3: CPC 27 DE 10/2020 - HTSP
A5: Conta | B5: Nome da conta | C5: Vida útil econômica estimada | D5: Valor residua l estimado | E5: Taxa mensal de despesa de depreciação | F5: Despesa de depreciação por mes | G5: Ajuste CPC - 27 | H5: Ajuste CPC - 27
A6: 135005 | B6: Edificacoes | C6: 40 | D6: 1 | E6: 0 | F6: 0 | G6: -26.67758 | H6: -26411.56
A7: 135010 | B7: Instalacoes | C7: 10 | D7: 0 | E7: 0.0379697 | F7: 339.60312 | G7: 0 | H7: 0
A8: - | B8: Sist De Comunicacao | C8: 0 | D8: 0 | E8: 0 | F8: 0 | G8: 0 | H8: 0
A9: 135015 | B9: Maquinas E Equipamentos | C9: 10 | D9: 0.1 | E9: 0.018444693 | F9: 20.079369 | G9: 2.9852486 | H9: 2532.29
A10: 135020 | B10: Equip Proc De Dados | C10: 5 | D10: 0.05 | E10: 0.051555787 | F10: 25.196231 | G10: 10.982621 | H10: 9826.02
A11: 135025 | B11: Moveis Utens Hosp | C11: 10 | D11: 0.05 | E11: 0.026594238 | F11: 75.033168 | G11: 15.080448 | H11: 16774.82
A12: 135030 | B12: Veiculos | C12: 7 | D12: 0.5 | E12: 0 | F12: 0 | G12: 0 | H12: 0
A13: - | B13: Obras De Arte | C13: 0 | D13: 0 | E13: 0 | F13: 0 | G13: 0 | H13: 0
A14: 135045 | B14: Material De Servicos | C14: 5 | D14: 0.05 | E14: 0.015669344 | F14: 5.7958066 | G14: -4.0111734 | H14: -4828.4
A15: 135050 | B15: Vidros E Cristais | C15: 5 | D15: 0.05 | E15: 0.015679487 | F15: 0.62843738 | G15: -0.40978262 | H15: -496.27
A16: 135040 | B16: Loucas E Porcelanas | C16: 5 | D16: 0.05 | E16: 0.015679122 | F16: 3.2343104 | G16: -1.9244896 | H16: -2354.41
A17: 135055 | B17: Prataria E Inox | C17: 5 | D17: 0.05 | E17: 0.015679012 | F17: 1.9769153 | G17: -1.2071847 | H17: -1472.66
E18: TOTAL | G18: -5.1818923 | H18: =SUM(H6:H17) -> -6430.17 | I18: 0.04 | J18: =H18*I18 -> -257.2068
H19: =H18-J18 -> -6172.9632
